Workbook
Name _Toc272312950: Synopsis!$B$48
Name _Toc281130000: val!#REF!
Name _Toc332296746: 'Limiting Condition'!$B$1
Name _Toc332296753: 'Legal Aspects'!#REF!
Name _Toc335642854: Importance!$B$1
Name _Toc335642855: Importance!#REF!
Name _Toc335642860: 'Limiting Condition'!$B$6
Name _Toc335642867: Sheet4!$A$1
Name _Toc335642868: Sheet4!$B$9
Name _Toc335642869: Sheet4!$B$11
Name _Toc341107988: Synopsis!$B$1
Name _Toc341107989: Synopsis!$B$2
Name _Toc341107990: Synopsis!$B$3
Name _Toc341107993: Location!$B$1
Name _Toc341107994: Location!$B$14
Name _Toc341107995: Location!$B$21
Name _Toc341107996: 'Description '!#REF!

Sheet In Put
A3: Client's Name | B3: M/S. Mokshya Trade & Suppliers
A4: Address
A5: Ward No | B5: 9
A6: VDC/ Municipality | B6: Tokha
A7: District | B7: Kathmandu
A8: Registration No. | B8: 147501/075/76
A9: Issued Date | B9: 076/01/11
A10: Issued Office | B10: Department of Commerce Supplies & Consumer Protection
A11: Proprietor's Name | B11: Mr. Binod Kumar Khatri
A12: PAN No: | B12: 602383466
A13: Contact No. | B13: 9851044761
A14: Property To be mortgaged | B14: Land & Building
A16: Client's Name | B16: Mr. Binod Kumar Khatri
A17: Address
A18: Ward No | B18: 7
A19: VDC/ Municipality | B19: Bhatauli
A20: District | B20: Ramechhap
A21: Citizenship No | B21: 11032/12466
A22: Issued Date | B22: 066/06/18
A23: Issued Office | B23: District Administrative Office, Ramechhap
A24: Father's Name | B24: Mr. Saha Bahadur Khatri
A25: Grand Father's Name | B25: Mr. Ram Bahadur Khatri
A26: Contact No. | B26: 9851044761
A29: Owner's Name | B29: Mrs. Lila Khatri
A30: Address
A31: Ward No | B31: 6
A32: VDC/ Municipality | B32: Bhimeshwor
A33: District | B33: Dolakha
A34: Citizenship No | B34: 221014
A35: Issued Date | B35: 068/06/06
A36: Issued Office | B36: District Administrative Office, Dolakha
A37: Husband's Name | B37: Mr. Binod Kumar Khatri
A38: Father in Law's Name | B38: Mr. Saha Bahadur Khatri
A39: Contact No. | B39: 9851044761
A42: Location of Site | B42: Tarkeshwor Municipality-01(Sabik Sangla VDC 09'Ka'), Kathmandu District
A43: Plot No | B43: 791
A44: Municipality/ VDC | B44: 1 | C44: 1 for Municipality & 0 for VDC

Sheet TOC
B1: =[1]Synopsis!_Toc341107988 -> Synopsis of Property Valuation Report
B2: Covering letter of consultant Engineer.
B3: =[1]Synopsis!_Toc341107989 -> 1. General Information
C4: =[1]Synopsis!_Toc341107990 -> a. Name, Address and General Information of Client
C5: =[1]Synopsis!B26 -> b. Property to be mortgaged
C6: =[1]Synopsis!_Toc272312950 -> c. Name , Address and General Information of Owner of Property
C7: =[1]Location!_Toc341107993 -> d. Location of Property
C8: =[1]Location!_Toc341107994 -> e. Total Area of Land
C9: =[1]Location!_Toc341107995 -> f. Parameter of Boundaries
C10: =[1]Importance!_Toc335642854 -> g. Importance of Location
C11: ='[1]Description '!B2 -> h. Description of Property
C12: A) Land
C13: B) Building
B14: ='[1]Legal Aspects'!B2 -> 2. Legal Aspects of Property
B15: =[1]summary!A1 -> 3. Summary of Valuation of Property
B16: ='[1]Limiting Condition'!_Toc332296746 -> 4. Limiting Conditions
B17: ='[1]Limiting Condition'!_Toc335642860 -> 5. Remarks
B18: ='[1]Limiting Condition'!B19 -> 6. Opinion
B19: =[1]Area!C1 -> 7. Site Measurement of Land (Area Calculation)
B20: 8. Methodology of Valuation
B21: 9. Location Map of the Property/ Triangulation
B22: 10. Copy of Government Rate
B23: ='Limiting Condition'!B28 -> 11. Commitment of Property Owner and Client
B24: ='Limiting Condition'!B40 -> 12. Certification
B25: Annex A: Photographs of Property
B26: Annex B: Supporting Legal Documents
B27: 1. Copy of Registration Certificate
B28: 2. Copy of PAN
B29: 3. Copy of Citizenship Certificate of Owner/ Client
B30: 4. Copy of Title Deed Certificate (Lal purja)
B31: 5. Land Revenue Payment Receipt
B32: 6. Four Boundary disclosure
B33: 7. Trace Map
B35: 8. Original Blue Print
B36: 9. Copy of Building Construction Approval Certificate
B37: 10. Copy of Building Construction Completion(Partial) Certificate
B38: 11. Copy of Approved Building Drawing

Sheet Synopsis
B1: Synopsis of Property Valuation Report
B2: 1. General Information
B3: a. Name, Address and General Information of Client
B5: 1 | C5: ='In Put'!A3 -> Client's Name | D5: : | E5: ='In Put'!B3 -> M/S. Mokshya Trade & Suppliers
C6: ='In Put'!A4 -> Address | D6: :
C7: ='In Put'!A5 -> Ward No | D7: : | E7: ='In Put'!B5 -> 9
C8: ='In Put'!A6 -> VDC/ Municipality | D8: : | E8: ='In Put'!B6 -> Tokha
C9: ='In Put'!A7 -> District | D9: : | E9: ='In Put'!B7 -> Kathmandu
C10: ='In Put'!A8 -> Registration No. | D10: : | E10: ='In Put'!B8 -> 147501/075/76
C11: ='In Put'!A9 -> Issued Date | D11: : | E11: ='In Put'!B9 -> 076/01/11
C12: ='In Put'!A10 -> Issued Office | D12: : | E12: ='In Put'!B10 -> Department of Commerce Supplies & Consumer Protection
C13: ='In Put'!A11 -> Proprietor's Name | D13: : | E13: ='In Put'!B11 -> Mr. Binod Kumar Khatri
C14: ='In Put'!A12 -> PAN No: | D14: : | E14: ='In Put'!B12 -> 602383466
C15: ='In Put'!A13 -> Contact No. | D15: : | E15: ='In Put'!B13 -> 9851044761
B18: 2 | C18: Client's Name | D18: : | E18: ='In Put'!B16 -> Mr. Binod Kumar Khatri
C19: Address
C20: Ward No | D20: : | E20: ='In Put'!B18 -> 7
C21: VDC/ Municipality | D21: : | E21: ='In Put'!B19 -> Bhatauli
C22: District | D22: : | E22: ='In Put'!B20 -> Ramechhap
C23: Citizenship No | D23: : | E23: ='In Put'!B21 -> 11032/12466
C24: Issued Date | D24: : | E24: ='In Put'!B22 -> 066/06/18
C25: Issued Office | D25: : | E25: ='In Put'!B23 -> District Administrative Office, Ramechhap
C26: ='In Put'!A24 -> Father's Name | D26: : | E26: ='In Put'!B24 -> Mr. Saha Bahadur Khatri
C27: ='In Put'!A25 -> Grand Father's Name | D27: : | E27: ='In Put'!B25 -> Mr. Ram Bahadur Khatri
C28: ='In Put'!A26 -> Contact No. | D28: : | E28: ='In Put'!B26 -> 9851044761
B44: b. Property to be mortgaged | D44: : | E44: ='In Put'!B14 -> Land & Building
B48: c. Name , Address and General Information of Owner of Property
C50: Name | D50: : | E50: ='In Put'!B29 -> Mrs. Lila Khatri
C51: Address
C52: Ward No | D52: : | E52: ='In Put'!B31 -> 6
C53: VDC/ Municipality | D53: : | E53: ='In Put'!B32 -> Bhimeshwor
C54: District | D54: : | E54: ='In Put'!B33 -> Dolakha
C55: Citizenship No | D55: : | E55: ='In Put'!B34 -> 221014
C56: Issued Date | D56: : | E56: ='In Put'!B35 -> 068/06/06
C57: Issued Office | D57: : | E57: ='In Put'!B36 -> District Administrative Office, Dolakha
C58: ='In Put'!A37 -> Husband's Name | D58: : | E58: ='In Put'!B37 -> Mr. Binod Kumar Khatri
C59: ='In Put'!A38 -> Father in Law's Name | D59: : | E59: ='In Put'!#REF! -> #REF!
C60: ='In Put'!A38 -> Father in Law's Name | D60: : | E60: ='In Put'!B38 -> Mr. Saha Bahadur Khatri
C61: Contact No. | D61: : | E61: ='In Put'!B39 -> 9851044761

Sheet Location
B1: d. Location of Property
B3: Plot No. | E3: : | F3: ='In Put'!B43 -> 791
B4: Location
B5: Ward No | E5: : | F5: 1
B6: VDC/ Municipality | E6: : | F6: ='In Put'!B42 -> Tarkeshwor Municipality-01(Sabik Sangla VDC 09'Ka'), Kathmandu District
B7: District | E7: : | F7: Kathmandu
B8: Type of Location | E8: : | F8: Residential
B9: Shape | E9: : | F9: Regular
B10: Nearest Market | E10: : | F10: Gongabu
B11: Distance from main road | E11: : | F11: 550m North-East from Bhatkya Pool Via Mega City.
B12: High Tension Line above the site | E12: : | F12: Not Seen
B14: e. Total Area of Land
F15: Ropani | G15: Anna | H15: Paisa | I15: Dama
B16: As per Lalpurja | E16: : | F16: =summary!D9 -> 0 | G16: =summary!F9 -> 2.9995 | H16: =summary!G9 -> 0 | I16: =summary!H9 -> 0
B17: As per Measurement | E17: : | F17: =summary!D10 -> 0 | G17: =summary!F10 -> 2 | H17: =summary!G10 -> 3 | I17: =summary!H10 -> 3.2
F18: (Refer to Attached Sheet. "Land Area Calculation")
B19: Area Considered for Valuation | E19: : | F19: =summary!D11 -> 0 | G19: =summary!F11 -> 2 | H19: =summary!G11 -> 3 | I19: =summary!H11 -> 3.2
B21: f. Parameter of Boundaries
A22: Certified By: Tarkeshwor Municipality, Ward Office-1, Dated 2079/09/07 Ref: 1492 -079/080.
C23: Plot No: | F23: East | G23: West | H23: North | I23: South
C24: =summary!A16 -> 791 | F24: =summary!C16 -> Plot no. 792 | G24: =summary!D16 -> Plot No.790 | H24: =summary!G16 -> Plot no. 785 | I24: =summary!I16 -> Road

Sheet Importance
B1: g. Importance of Location
B2: The Property is located at Tarkeshwor Municipality-01(Sabik Sangla VDC 09'Ka'), Kathmandu District. The site can be accessed from Bhatkya Pool and Travelling around 550m North-East from Bhatkya Pool Via Mega City, We can reach this Property.
B4: Followings are the some of the merits of the location
C5: =summary!A30 -> The Considered Site is resindential area located at Mega City,Sangla.
C6: Physical Infrastructure like Sanitary ,Water Supply, Tv cable, electricity are developed in the area.
C7: =summary!A31 -> Approx. 550m North-East from Bhatkya Pool Via Mega City.
C8: =summary!A32 -> Access Road to the considered site is 13ft wide Concerete Road at South side.
C9: =summary!A33 -> Public Transportation is 5min walking distance from the considered site.
C10: =summary!A34 -> Physical Infrastructure like Sewerage line, Water Supply, Telephone,Tv Cable, Electricity Line are available in the considered site

Sheet Description 
B2: h. Description of Property
B4: A. LAND
A6: 1 | B6: Type of ownership | D6: : | E6: Single
A7: 2 | B7: Shape of the Land | D7: : | E7: Regular
A8: 3 | B8: Level of the Land | D8: : | E8: General
A9: 4 | B9: Topography of Land | D9: : | E9: Plain
A10: 5 | B10: Nature of soil | D10: : | E10: N/A
A11: 6 | B11: Access of the Land | D11: : | E11: 13ft Wide Concrete Slab Road
A12: 7 | B12: Any Construction on the Land | D12: : | E12: RCC Building
A13: 8 | B13: Sewer facility on the Land | D13: : | E13: Yes
A14: 9 | B14: Water supply facility on that Area | D14: : | E14: Yes
A15: 10 | B15: Electricity Supply on that Area | D15: : | E15: Yes
A16: 11 | B16: Nature of the Area | D16: : | E16: Residential
A17: 12 | B17: Whether the Land is located below the high tension electric line | D17: : | E17: No
A18: 13 | B18: Address of the Land | D18: : | E18: ='In Put'!B42 -> Tarkeshwor Municipality-01(Sabik Sangla VDC 09'Ka'), Kathmandu District
A19: 14 | B19: Positive Feature of Land | D19: : | E19: N/A
A20: 15 | B20: Any Negative Feature of The area | D20: : | E20: N/A
B31: B. BUILDING
A32: 1 | B32: Type of ownership | D32: : | E32: Single
A33: 2 | B33: Purpose of the Building | D33: : | E33: Residential
A34: 3 | B34: No of floor of the Building Constructed | D34: : | E34: 3& half floor
A35: 4 | B35: Total Sq ft of Building In Dwg. | D35: : | E35: =val!E25 -> 2835.76
A36: 5 | B36: Type of the Building's Structure | D36: : | E36: RCC Frame Structure
A37: 6 | B37: Thickness of Slab | D37: : | E37: 5"
A38: 7 | B38: Thickness of Wall | D38: : | E38: 9"
A39: 8 | B39: Height of each Floor of Building | D39: : | E39: 9'
A40: 10 | B40: Total Height of Building | D40: : | E40: 41'-11"
A41: 11 | B41: Breadth of Building | D41: : | E41: 29'-02"
A42: 12 | B42: Length of Building | D42: : | E42: 29'-09"
A43: 9 | B43: Type of Foundation of Building | D43: : | E43: Isolated
A44: 10 | B44: Age of the Building | D44: : | E44: 0 Years
A45: 11 | B45: Expected life of Building | D45: : | E45: 45 Years
A46: 12 | B46: Any Construction on the Land | D46: : | E46: Yes
A47: 13 | B47: Sewer facility in the building | D47: : | E47: Yes
... A56: 22 | B56: Repair and Maintenance | D56: : | E56: No
A57: 23 | B57: Address of the Building | D57: : | E57: =E25 -> 0
B59: 4.2 Current Rate of Major Building Materials
A60: S.No | B60: Description of Materials | C60: Rate (NRs.) | E60: Units
A61: 1 | B61: Local Bricks | C61: 14.54 | E61: No.
A62: 2 | B62: Cement | C62: 680 | E62: Bags
...

Sheet Legal Aspects
B2: 2. Legal Aspects of Property
B3: A number of local people and landowners in the vicinity were interviewed and to the best of our knowledge , no legal dispute has been recorded. Ownership of property has been verified on the basis of Title Deed Certificate (Lalpurja), interview with Client and the Local People during the field survey in Jan 30, 2023.
B8: Following legally related documents have been checked and noted which are provided by the bank & client as under:
B9: Land
B10: Land Ownership Document (Lalpurja)
B11: a) | C11: Type of Ownership | D11: : | E11: Single
B12: b) | C12: Ownership of Land | D12: : | E12: Freehold
B13: c) | C13: Name of the Owner | D13: : | E13: ='In Put'!B29 -> Mrs. Lila Khatri
B14: d) | C14: Comments, if any | D14: : | E14: None
B15: Land Revenue (Malpot)
B16: a) | C16: Wheather the Current/Revenue has been paid | D16: : | E16: Yes
B17: b) | C17: Date of Payement of Receipt | D17: : | E17: 2079/ /
B18: c) | C18: Comments, if any | D18: : | E18: No
B20: Land Registration Paper
B21: a) | C21: Wheather Normal Sale/Gift | D21: : | E21: Sale
B22: b) | C22: Date of Registration | D22: : | E22: 2075/05/12
B23: c) | C23: Wheather 6 Month 35 days in case of Normal Sale and 2 years 35 days in case of Gift has elapsed | D23: : | E23: Yes
B24: d) | C24: Comments, if any | D24: : | E24: N/A
B26: Maps of the Plots prepared by Government Survey Department
B27: a) | C27: Whether the plots are indicated | D27: : | E27: Yes
B28: b) | C28: Whether access is clearly marked on the map prepared by Government Survey Department | E28: Yes
B29: c) | C29: Whether the shape of the land in the field tally with the map | D29: : | E29: Yes
B30: d) | C30: Comments, if any | D30: : | E30: N/A
B32: e) | C32: Whether the area of land increased or decreased compared to the recorded in the existing land Ownership Document | D32: : | E32: Decreased
B33: f) | C33: Comments, if any | D33: : | E33: N/A
C36: Certificate of Parameters of Boundary
B37: a) | C37: Is the Parameters of Boundary Available | D37: : | E37: Yes
B38: b) | C38: Date of Certification | E38: 2079/09/07
B39: c) | C39: Comments, if any | D39: : | E39: None
C42: General
B43: a) | C43: Whether free access to the property is Available | D43: : | E43: Yes
B44: b) | C44: Has whole or part of the land been notified or acquisition for any other purpose by the Government of any other statutory body | D44: : | E44: No
B45: c) | C45: Whether the boundary of the property is clearly defined at the site | D45: : | E45: Yes
B46: d) | C46: Comments, if any | D46: : | E46: No
B48: Building
B49: 1 | C49: Approved Drawing of Building | E49: Yes
B50: 2 | C50: Approval of Construction from VDC | E50: Yes
B51: 3 | C51: Construction Completion Certificate | E51: N/A
B52: 4 | C52: Tax Clearance Certificate of Building | E52: N/A

Sheet Summary1
A1: 3. Summary of Valuation of Property 1
A2: Valuation Date: | B2: 02 Feb, 2023 | F2: Survey Date: | H2: =summary!O2 -> 44956
A3: Valuer Name | B3: Er. Sukhla Deep Shrestha | E3: (All the given amounts are in Nepalese Rupees i.e. NPR)
A4: Client's Name | B4: M/S. Mokshya Trade & Suppliers & Mr. Binod Kumar Khatri
A5: Current Property Owner Name | B5: ='In Put'!B29 -> Mrs. Lila Khatri
A6: Property Address | B6: ='In Put'!B42 -> Tarkeshwor Municipality-01(Sabik Sangla VDC 09'Ka'), Kathmandu District
A7: Plot No. | B7: ='In Put'!B43 -> 791
E8: Four Wall Boundary of the Property :
E9: Plot no. | F9: East | G9: West | H9: North | I9: South
A10: Location | B10: Mega City, Sangla, Tarkeshwor Municipality | E10: =summary!A16 -> 791 | F10: =summary!C16 -> Plot no. 792 | G10: =summary!D16 -> Plot No.790 | H10: =summary!G16 -> Plot no. 785 | I10: =summary!I16 -> Road
A11: Metropolitan City / Municipality | B11: Tarkeshwor Municipality
A12: District | B12: Kathmandu
A14: Valuation For | C14: Vacant Land | F14: Land & Building | H14: Readymade House
C15: Apartments / Duplex | F15: Construction/Extension/Renovation
A17: Motorable Access | C17: Yes | E17: No
A18: River / stream near property | C18: Yes | E18: No
A19: Heritage/Memorial sites near property | C19: Yes | E19: No
A20: Property Type | C20: Residential | E20: Commercial | G20: Industrial | I20: Agricultural
A21: Property Ownership Type | C21: Company | E21: Individual (Single name) | H21: Individual (Joint name)
A22: Ownership transferred through | C22: Sale | E22: Bakaspatra | G22: Family Separation
A23: Hold Type | C23: Freehold | E23: Leasehold
A24: Residual Age of the Property | C24: Years
B26: Area (Square meter) | D26: Commercial rate Per Aana | E26: Govt.rate Per Aana | F26: Fair Market Value (FMV) | H26: Distress Value (DV)(80%of FMV)
A27: Land Value | B27: =summary!I11 -> 93.79856 | D27: =val!F10 -> 3500000 | E27: =val!F9 -> 560000 | F27: =val!G41 -> 7723100 | H27: =val!H41 -> 6178480
A29: Building Value | B29: =val!E25 -> 2835.76 | C29: (Sq.ft) | D29: =val!G36 -> 10917676 | F29: =val!F42 -> 10917676 | H29: =val!H42 -> 8734140.8
A30: Apartment Value
A31: Construction Value
A32: Extension / Renovation Value
A33: Total | F33: =SUM(F27:G32) -> 18640776 | H33: =SUM(H27:I32) -> 14912621
A34: TOTAL VALUE : | E34: Say | F34: =summary!H23 -> 18640000 | H34: =summary!J23 -> 14912000
A35: =val!A45 -> On the basis of the details provided by Client and Field verification, At Present Fair Market Value of property is 18,640,000.00 In Words: NRs Eighteen Million and Six Hundred and Forty Thousands Only. At Present Distress Value of property is 14,912,000.00 In Words: NRs Fourteen Million Nine Hundred and Twelve Thousands Only.
A36: Special Comments :
A37: 1. ROW (Right of Way) No. deduction has been done .
A38: 2.The property does not have any danger of flood & land slide
A39: 3.Statements of fact are true and correct
A40: 4.We have no interest in the transaction of property
A41: 5.An inspection of the property has been done.
A42: 6. The building is constructed on the land.
A43: 7.The property does not have any issues related to access, ownership, saleability,etc. based on the review of the required land ownership documents, blue print, tansfer document and as verified by us with the respective Land Revenue ( Malpot) Office.
A46: As a collateral security for the Banking Facilities, the property is
...

Sheet summary
A1: 3. Summary of Valuation of Property 2
A2: =val!A2 -> Client's Name | H2: : | I2: M/S. Mokshya Trade & Suppliers Mr. Binod Kumar Khatri | M2: Date of Survey: | O2: 44956
A3: Type of Property to be mortgaged | H3: : | I3: ='In Put'!B14 -> Land & Building
A4: Plot No | H4: : | I4: ='In Put'!B43 -> 791
A5: Location | H5: : | I5: ='In Put'!B42 -> Tarkeshwor Municipality-01(Sabik Sangla VDC 09'Ka'), Kathmandu District
A6: =val!A6 -> Owner's Name | H6: : | I6: ='In Put'!B29 -> Mrs. Lila Khatri
A7: Area of the land
D8: R | F8: A | G8: P | H8: D | I8: Sqm
A9: As per Lalpurja | D9: =Area!E25 -> 0 | F9: =Area!F25 -> 2.9995 | G9: 0 | H9: 0 | I9: =D9*508.737+F9*31.7961+G9*7.949+H9*1.9873 -> 95.372402
A10: As per measurement | D10: 0 | F10: 2 | G10: 3 | H10: 3.2 | I10: =D10*508.737+F10*31.7961+G10*7.949+H10*1.9873 -> 93.79856
A11: Area Considered | D11: 0 | F11: 2 | G11: 3 | H11: 3.2 | I11: =D11*508.737+F11*31.7961+G11*7.949+H11*1.9873 -> 93.79856
A14: Parameters of Four Boundary | J14: Accessability
A15: Plot No. | C15: East | D15: West | G15: North | I15: South | J15: The said site is linked via 13ft wide Concrete Slab Road at South Side. The site can be accessed from Bhatkya Pool and Travelling around 550m North-East from Bhatkya Pool Via Mega City, We can reach this Property.
A16: ='In Put'!B43 -> 791 | C16: Plot no. 792 | D16: Plot No.790 | G16: Plot no. 785 | I16: Road
A17: Value of the Property:
A19: S.N | B19: Particulars | D19: Market Value (NRs) | H19: FMV (NRs) | J19: Distress Value(NRs) | M19: =val!A45 -> On the basis of the details provided by Client and Field verification, At Present Fair Market Value of property is 18,640,000.00 In Words: NRs Eighteen Million and Six Hundred and Forty Thousands Only. At Present Distress Value of property is 14,912,000.00 In Words: NRs Fourteen Million Nine Hundred and Twelve Thousands Only.
A20: 1 | B20: Land | D20: =val!G10 -> 10325000 | H20: =val!G11 -> 7723100 | J20: =val!H41 -> 6178480
A21: 2 | B21: Building | D21: =val!G36 -> 10917676 | H21: =val!G36 -> 10917676 | J21: =val!H42 -> 8734140.8
A22: Total Amount | D22: =SUM(D20:G21) -> 21242676 | H22: =SUM(H20:I21) -> 18640776 | J22: =SUM(J20:L21) -> 14912621
A23: Say | D23: =val!F44 -> 21242000 | H23: =val!G44 -> 18640000 | J23: =val!H44 -> 14912000
A24: Access Road
A28: Width of the Road: | D28: 13 | G28: Ft
A29: Remarks:
A30: The Considered Site is resindential area located at Mega City,Sangla.
A31: Approx. 550m North-East from Bhatkya Pool Via Mega City.
A32: Access Road to the considered site is 13ft wide Concerete Road at South side.
A33: Public Transportation is 5min walking distance from the considered site.
A34: Physical Infrastructure like Sewerage line, Water Supply, Telephone,Tv Cable, Electricity Line are available in the considered site

Sheet val
A1: Valuation Of Property
A2: ='In Put'!A3 -> Client's Name | C2: : | D2: M/S. Mokshya Trade & Suppliers Mr. Binod Kumar Khatri | G2: Date of Survey: | H2: =summary!O2 -> 44956
A3: Type of Property to be motgaged | C3: : | D3: ='In Put'!B14 -> Land & Building
A4: Plot No | C4: : | D4: ='In Put'!B43 -> 791
A5: Location | C5: : | D5: ='In Put'!B42 -> Tarkeshwor Municipality-01(Sabik Sangla VDC 09'Ka'), Kathmandu District | J5: =1037.53/342.25 -> 3.0314974
A6: ='In Put'!A29 -> Owner's Name | C6: : | D6: ='In Put'!B29 -> Mrs. Lila Khatri
A7: Value of Land
A8: S.N | B8: Particulars | C8: Plot No: | E8: Area of Land (Anna) | F8: Rate per Aana | G8: Amount | H8: Remarks | J8: =1048.14/342.25 -> 3.0624982
A9: 1 | B9: Total Government value of land | C9: =D4 -> 791 | E9: 2.95 | F9: 560000 | G9: =E9*F9 -> 1652000 | H9: Rs 5 Lakh 60 Thousands Per Aana as per gov Rate
A10: 2 | B10: Total Market Value of Land | E10: =E9 -> 2.95 | F10: 3500000 | G10: =F10*E10 -> 10325000 | H10: As from Local People and the judgement of the valuator | K10: 13.63
B11: Fair Market Value of Land | G11: =G9*0.3+G10*0.7 -> 7723100 | H11: Sum of 30% of SN1 and 70% of SN2 | K11: =1026.18/342.25 -> 2.9983346 | O11: =87.42*10.76 -> 940.6392
B12: Average Rate of Land per Anna (Taking weightage 30% of Gov Rate and 70% of market Rate) | G12: =F9*0.3+F10*0.7 -> 2618000
B14: 35% Of Government Value Of Land | F14: =G9*0.3 -> 495600
B15: 65% Of Market Value Of Land | F15: =G10*0.7 -> 7227500 | P15: =4250000*0.15% -> 6375
B16: Total Fair Market Value of Land | F16: =F14+F15 -> 7723100
A18: Value of Building :
A19: Structural System | G19: RCC
A20: SN | B20: Particulars | C20: Unit | E20: Quantity | F20: Rate | G20: Amount | H20: Remarks
A21: 1 | B21: Ground Floor | C21: Sqft | E21: 716.25 | F21: 3500 | G21: =E21*F21 -> 2506875
A22: 2 | B22: First Floor | C22: Sqft | E22: 755.25 | F22: 3500 | G22: =E22*F22 -> 2643375
A23: 3 | B23: Second Floor | C23: Sqft | E23: 755.25 | F23: 3500 | G23: =E23*F23 -> 2643375
A24: 4 | B24: Third Floor | C24: Sqft | E24: 609.01 | F24: 3500 | G24: =E24*F24 -> 2131535
B25: Total Floor | C25: Sqft | E25: =SUM(E21:E24) -> 2835.76
B26: Total Cost of Civil Works | G26: =SUM(G21:G25) -> 9925160
B27: Sanitary and Water Supply @ 5 % of Civil works | G27: =G26*0.05 -> 496258
B28: Electrical @ 5 % of Civil works | G28: =G26*0.05 -> 496258
B29: Total Cost of the Building | G29: =SUM(G26:G28) -> 10917676
A30: Value of Building | F30: NRs: | G30: =G29 -> 10917676
A31: Life of Building Considered | F31: : | G31: 45 | H31: yrs
A32: Age of Building | G32: 0 | H32: yrs
A33: Depreciation Rate | F33: : | G33: 0.0225
A34: Total Depreciation | G34: =G33*G32 -> 0
A35: Amount of Depreciation | F35: NRs: | G35: =G30*G34 -> 0
A36: Net Value of Building | F36: NRs: | G36: =G30-G35 -> 10917676
A37: Average Rate of the floor per sqft (After necessary addition & deduction) | F37: NRs: | G37: =G36/E25 -> 3850
A39: VALUATION OF THE PROPERTY
A40: S.N. | B40: Particulars | F40: Commercial Value(NRs.) | G40: Fair Market Value(NRs.) | H40: Distress Value (80% of FMV )(NRs.)
A41: 1 | B41: At Present | C41: 1 | D41: Land | F41: =G10 -> 10325000 | G41: =G11 -> 7723100 | H41: =G41*0.8 -> 6178480
C42: 2 | D42: Building | F42: =G36 -> 10917676 | G42: =F42 -> 10917676 | H42: =G42*0.8 -> 8734140.8
E43: Total | F43: =SUM(F41:F42) -> 21242676 | G43: =SUM(G41:G42) -> 18640776 | H43: =SUM(H41:H42) -> 14912621
...

Sheet Limiting Condition
B1: 4. Limiting Conditions
B2: a) The opinion of Value Stated is based on the facts and assumptions identified in this report. The valuator takes no responsibility for changes in market conditions.
B3: b) The opinion of value stated is based on the information that has been available to the valuator at the time; the valuation analysis has been conducted. The Value of the Property may change substantially with time and Valuator reserves the right to alter the Opinion of Value Stated if relevant information is available later.
B6: 5. Remarks
B8: 1 | C8: =summary!A30 -> The Considered Site is resindential area located at Mega City,Sangla.
B9: 2 | C9: Ownership of the land is Free Hold and is in the name of Mrs. Lila Khatri.
B10: 3 | C10: Access road to the considered property is via under the adjacent building.
B11: 3 | C11: =summary!A31 -> Approx. 550m North-East from Bhatkya Pool Via Mega City.
B12: 4 | C12: =summary!A32 -> Access Road to the considered site is 13ft wide Concerete Road at South side.
B13: 5 | C13: The considered Property lies in Tarkeshwor Municipality-01(Sabik Sangla VDC 09'Ka'), Kathmandu District.
B14: 6 | C14: =summary!A33 -> Public Transportation is 5min walking distance from the considered site.
B15: 7 | C15: =summary!A34 -> Physical Infrastructure like Sewerage line, Water Supply, Telephone,Tv Cable, Electricity Line are available in the considered site
B17: To the best of our knowledge , all matter of factual nature discussed in this Report are true and correct. No important factors have been intentionally overlooked or withheld.
B19: 6. Opinion
B21: In our opinion, the Property may be taken as mortgage for the Bank value recommended in the Property Valuation Report. However, all the remarks made above shall be taken into consideration and all Legal Documents shall be scrutinized by Legal Expert. The said properties have been verified after visiting the site and measuring it as shown by the Client for the purpose of mortgaging it in M/S Kamana Sewa Bikas Bank Ltd.
B28: 11. Commitment of Property Owner and Client
B30: We are fully responsible for the information and legal document provided to prepare this valuation report. We are commited, and there is no legal complication. It is not being acquired by government, and it is not a prohibited area for construction.
B34: Signature | G34: Signature
B35: ='In Put'!B29 -> Mrs. Lila Khatri | G35: ='In Put'!B3 -> M/S. Mokshya Trade & Suppliers
B36: Property Owner | G36: Client
B40: 12. Certification
B41: I/We hereby certify that Valuation of the Properties as detailed in this report has been carried out by me/us in strict Compliance with Valuation Guidelines of M/S Kamana Sewa Bikas Bank Ltd. The said property is an acceptable security to bank in all respects.
B46: Checked By | G46: Checked By
B47: Er.Nabin Chandra Ghimire | G47: Er. Sukhla Deep Shrestha
B48: Mobile No. 9851316737 | G48: Mobile No. 9851246415

Sheet Area
C1: 7. Site Measurement of Land (Area Calculation)
C2: The Land area is calculated in accordance to the measurement taken in the field and reference from the government survey sheet(blue print) and trace map. The land area is also referred to from the approved architectural drawing of building.
C5: Triangulation method is adopted for the determination of the actual area of land. The dimension of land is given in the separate sheet, which is attached along with this report in the Appendix
C8: Mathematically, the area A of a triangle is given by
C9: A= ` √s(s-a)(s-b)(s-c)
B11: A. | C11: Total Land area as per Measurement or Trace paper: | J11: =6/12 -> 0.5 | K11: =4/12 -> 0.33333333
C12: Triangle | D12: Side a | E12: Side b | F12: Side c | G12: S=(a+b+c)/2 | H12: Total area in Sqft. | I12: Land in Ana
C13: Plot No. | D13: ='In Put'!B43 -> 791 | J13: 1 | K13: =J13/12 -> 0.083333333 | M13: =4/12 -> 0.33333333
C14: A | D14: 29.25 | E14: 34.67 | F14: 45.33 | G14: =(D14+E14+F14)/2 -> 54.625 | H14: =(G14*(G14-D14)*(G14-E14)*(G14-F14))^0.5 -> 507.04828 | I14: =H17/342.25 -> 2.9501682 | J14: 2 | K14: =J14/12 -> 0.16666667
C15: B | D15: 29.5 | E15: 34.08 | F15: 45.33 | G15: =(D15+E15+F15)/2 -> 54.455 | H15: =(G15*(G15-D15)*(G15-E15)*(G15-F15))^0.5 -> 502.64679
G16: Total = | H16: =SUM(H14:H15) -> 1009.6951 | J16: 4 | K16: =J16/12 -> 0.33333333 | L16: =7/12 -> 0.58333333
G17: TOTAL = | H17: =H16 -> 1009.6951 | J17: 5 | K17: =J17/12 -> 0.41666667
G18: Area in Sqm. | H18: =H17/10.7639 -> 93.803832 | J18: 6 | K18: =J18/12 -> 0.5
J20: 8 | K20: =J20/12 -> 0.66666667
B21: B. | C21: Total Land area as per Lalpurja: | J21: 9 | K21: =J21/12 -> 0.75 | N21: =10.75*9.42 -> 101.265
C22: Land Information | E22: Land Area | J22: 10 | K22: =J22/12 -> 0.83333333 | Q22: =141.36+7.94 -> 149.3
C23: Location | D23: Plot no. | E23: Area in Anna | I23: Area in Sqft. | J23: 11 | K23: =J23/12 -> 0.91666667
E24: Ropani | F24: Anna | G24: Paisa | H24: Dam | O24: =3252400*0.15% -> 4878.6
C25: ='In Put'!B42 -> Tarkeshwor Municipality-01(Sabik Sangla VDC 09'Ka'), Kathmandu District | D25: =D13 -> 791 | E25: 0 | F25: 2.9995 | G25: 0 | H25: 0 | I25: =(E25*16*342.25)+(F25*342.25)+(G25/4)*342.25+(H25/16)*342.25 -> 1026.5789
K26: =I28/31.79 -> 3.0000752
I27: =SUM(I25:I26) -> 1026.5789
G28: Area in Sqm. = | I28: =I27/10.7639 -> 95.372391
C31: Area as per measurement | E31: : | F31: =H17 -> 1009.6951 | G31: Sqft
C32: Area as per Lalpurja | E32: : | F32: =I27 -> 1026.5789 | G32: Sqft
C33: Area considered for Valuation | E33: : | F33: =F31 -> 1009.6951 | G33: Sqft
L34: =258000/31.79 -> 8115.7597
L35: =L34*72.79 -> 590746.15

Sheet Sheet4
A1: Methodology of Valuation
A3: 1 | B3: Value of Land has been taken by Direct Comparison with Capitalized Value of Similar Land in the locality. It has been taken on the basis of interview with Client and Local People during field survey. The main factors considered for Valuation are Prevailing Market Price of Land in this area, topography, shape , approach road, importance of location, possibilities of future development etc.
B4: 2 | C4: Between the area of land as per Lalpurja and Area of Land as per | D4: Measurement , the | E4: area of land whichever is less has been considered.
B5: 3 | C5: Fair Market Value is calculated based on 40% of Government Rate as | D5: recommended | E5: by Land Revenue Department, Government of Nepal and 60% of | F5: Prevailing Market Rate is taken.
A7: Rate per sqft of building: Depending upon current rate of the building material and other items, the average reasonable rate of the building is NRs. 2300.00 per Sqft. For each floor of the building.
A8: Cost of fixtures ( electricity and sanitary): Depending upon current rate of fixture material materials and other items, the reasonable rate of the fixtures are 5% for electricity and 5% for sanitary from the cost of the civil works for the total building cost.
B9: Declaration of the Valuator
B10: The valuator declares that it has no interest, financially or otherwise in the property | C10: or with the client or property owner.
B11: Terminologies Used
B12: Current Prevailing Market Value: The current prevailing market value is the most | C12: ongoing market value at the time of observation, which is obtained from the local | D12: residents, brokers and the owner.
B13: Government Value: The minimum government registration rate fixed by Malpot | C13: Office of the concerned district is taken to calculate the government value of the land | D13: under consideration.
B14: Fair Market Value: Fair market value is the in-between value of prevailing market | C14: value and the government value, whereby it is calculated by allowing 60% weight to | D14: the prevailing market rate and 40% weight to the government rate.
B15: Client : The Client is the person/ company who wish to take service from the | C15: institution.
B16: Owner: The owner is the person or people who provides support for the Client by | C16: providing available fixed assets to the institution on behalf of the Client in legal | D16: mode.
B17: Lalpurja : Lalpurja (Title Deed Document) is the legal document provided by the | C17: government authority to the land owner specifying the ownerhip.
B18: Cadastral Map : Cadastral Map is the map issued by Land Revenue Department | C18: indicating the plot no, road , river, etc.

Sheet Sheet3

Sheet Sheet2
B3: S.N. | C3: Owner of the property | D3: Location of Property | E3: Details of Land | I3: Description of the Building
E4: Plot no. | F4: As Per Measurement (Sq. m) | G4: As Per Lalpurja (Sq.m) | H4: FMV | I4: Status | J4: Area Sq. ft. | K4: Amount
B5: 1 | C5: =val!D2 -> M/S. Mokshya Trade & Suppliers Mr. Binod Kumar Khatri | D5: ='In Put'!B42 -> Tarkeshwor Municipality-01(Sabik Sangla VDC 09'Ka'), Kathmandu District | E5: ='In Put'!B43 -> 791 | F5: =Area!H18 -> 93.803832 | G5: =Area!I28 -> 95.372391 | H5: 4072000 | I5: At Present | J5: =val!E21 -> 716.25 | K5: 2843000
F6: Area Considered
F7: =G5 -> 95.372391
I8: Length | J8: Breadth | K8: Height
E9: At Present | I9: ='Description '!E42 -> 29'-09" | J9: ='Description '!E41 -> 29'-02" | K9: ='Description '!E40 -> 41'-11"
B10: Total Fair Market Value of Land & Building Project | J10: =val!G44 -> 18640000
B11: Total Distress Value of Land & Building Project | J11: =val!H44 -> 14912000

Sheet Sheet1
A4: Tentative Estimate for Building Project
A5: Particulars | B5: Unit | C5: Estimation for Completion | F5: Progress upto date | I5: Required Amount for Completion
C6: Quantity | D6: Rate | E6: Amount | F6: Quantity | G6: Rate | H6: Amount
A7: Ground Floor | B7: Sqft | C7: =val!#REF! -> #REF! | D7: 3500 | E7: =D7*C7 -> #REF! | F7: =C7 -> #REF! | G7: =val!#REF! -> #REF! | H7: =G7*F7 -> #REF! | I7: =E7-H7 -> #REF!
A8: First Floor | B8: Sqft | C8: =val!#REF! -> #REF! | D8: 3300 | E8: =D8*C8 -> #REF! | F8: =C8 -> #REF! | G8: =val!#REF! -> #REF! | H8: =G8*F8 -> #REF! | I8: =E8-H8 -> #REF!
A9: Second Floor | B9: Sqft | C9: =val!#REF! -> #REF! | D9: 3300 | E9: =D9*C9 -> #REF! | F9: =C9 -> #REF! | G9: =val!#REF! -> #REF! | H9: =G9*F9 -> #REF! | I9: =E9-H9 -> #REF!
A10: Total Floor | B10: Sqft | C10: =SUM(C7:C9) -> #REF! | F10: =SUM(F7:F9) -> #REF!
A11: Total of Civil Cost | E11: =SUM(E7:E10) -> #REF! | H11: =SUM(H7:H10) -> #REF! | I11: =SUM(I7:I10) -> #REF!
A12: Electrical & Sanitary Cost @ 10% of Civil Cost | E12: =0.1*E11 -> #REF! | H12: =H11*0.1 -> #REF! | I12: =E12-H12 -> #REF!
E13: =SUM(E11:E12) -> #REF! | H13: =SUM(H11:H12) -> #REF! | I13: =E13-H13 -> #REF!
A15: Total Estimated amount for the Project | I15: =E13 -> #REF!
A16: In words NRs. Ninety Three Lakh Thirty Six Thousand Only. | H16: Say | I16: 9336000
A18: Required amount for completion of remaining works | I18: =I13 -> #REF!
A19: In words Nrs. Twenty Lakh Eighty Four Thousand Only. | H19: Say | I19: 2084000

Sheet Sheet5
G9: =45.75/3.28 -> 13.948171 | I9: =45.67-24 -> 21.67 | L9: =22-I10 -> 15.393293
I10: =I9/3.28 -> 6.6067073 | L10: =L9/2 -> 7.6966463
L11: =24/3.28 -> 7.3170732
M18: =9*4 -> 36
